Workbook

Sheet Report
A1: Gender Reporting
A3: Count of Name | B3: Reporting Status
A4: Gender | B4: PG | C4: Home | D4: Grand Total
A5: Female | B5: 681 | C5: 54 | D5: 735 | E5: =D5/D7 -> 0.42584009
A6: Male | B6: 921 | C6: 70 | D6: 991 | E6: =D6/D7 -> 0.57415991
A7: Grand Total | B7: 1602 | C7: 124 | D7: 1726
B8: =B7/D7 -> 0.92815759 | C8: =C7/D7 -> 0.07184241 | D8: 1 | E8: 1
A12: Reporting Status | B12: PG
A13: Nodal Point Table | D13: Relatives Located in chennai table | G13: Floor wise Table
A14: Grouping | B14: Count of Name | D14: Relatives in Chennai | E14: Count of Name | G14: Floor | H14: Count of Name
A15: Kelambakkam | B15: 17 | D15: No | E15: 1346 | G15: 1 | H15: 461
A16: Sholinganallur | B16: 28 | D16: Yes | E16: 380 | G16: 2 | H16: 383
A17: Siruseri | B17: 1551 | D17: Grand Total | E17: 1726 | G17: 3 | H17: 327
A18: Vandalur | B18: 1 | G18: 4 | H18: 256
A19: Velachery | B19: 5 | G19: 5 | H19: 82
A20: Grand Total | B20: 1602 | D20: Reporting from Table | G20: 6 | H20: 5
D21: Reporting from | E21: Count of Name | G21: 7 | H21: 7
D22: Hostel | E22: 36 | G22: 8 | H22: 1
D23: Permanent Residence (House/Home) | E23: 58 | G23: 10 | H23: 6
D24: PG (Paying Guest) | E24: 1566 | G24: 11 | H24: 2
D25: Rented House/Apartment | E25: 54 | G25: 12 | H25: 1
D26: Relatives Residence | E26: 12 | G26: 13 | H26: 1
D27: Grand Total | E27: 1726 | G27: 17 | H27: 1
G28: 18 | H28: 2
G29: 19 | H29: 1
A30: Projection Candidates count until Dec-26 | G30: 21 | H30: 1
A31: Sep 2026 | B31: Oct 2026 | C31: Nov 2026 | D31: Dec 2026 | G31: 23 | H31: 2
A32: =COUNTIF(Base!J:J,"Sep 2026")+COUNTIF(Base!J:J,"Oct 2026")+COUNTIF(Base!J:J,"Nov 2026")+COUNTIF(Base!J:J,"Dec 2026")+40 -> 1766 | B32: =COUNTIF(Base!J:J,"Oct 2026")+COUNTIF(Base!J:J,"Nov 2026")+COUNTIF(Base!J:J,"Dec 2026")+40 -> 1414 | C32: =COUNTIF(Base!J:J,"Nov 2026")+COUNTIF(Base!J:J,"Dec 2026")+40 -> 971 | D32: =COUNTIF(Base!J:J,"Dec 2026")+40 -> 531 | G32: GF | H32: 187
G33: Grand Total | H33: 1726
A35: Zone | B35: Count of Name
A36: Amber | B36: 25
A37: Red | B37: 1586
A38: N/A | B38: 115
A39: Grand Total | B39: 1726
A42: Reporting Status | B42: PG
A44: Count of Name | B44: Release Month | C44: Gender
B45: Sep 2026 | D45: Sep 2026 Total | E45: Oct 2026 | G45: Oct 2026 Total | H45: Nov 2026 | J45: Nov 2026 Total | K45: Dec 2026 | M45: Dec 2026 Total | N45: Grand Total
A46: Zone | B46: Female | C46: Male | E46: Female | F46: Male | H46: Female | I46: Male | K46: Female | L46: Male
A47: Amber | B47: 4 | C47: 4 | D47: 8 | F47: 1 | G47: 1 | I47: 3 | J47: 3 | K47: 4 | L47: 2 | M47: 6 | N47: 18
A48: Red | B48: 134 | C48: 185 | D48: 319 | E48: 169 | F48: 252 | G48: 421 | H48: 176 | I48: 218 | J48: 394 | K48: 194 | L48: 256 | M48: 450 | N48: 1584
...

Sheet Sheet1
F14: Gender Reporting
F16: Count of Name | G16: Reporting Status
F17: Gender | G17: PG | H17: Home | I17: Grand Total
F18: Female | G18: 681 | H18: 54 | I18: 735 | J18: =I18/I20 -> 0.42584009
F19: Male | G19: 921 | H19: 70 | I19: 991 | J19: =I19/I20 -> 0.57415991
F20: Grand Total | G20: 1602 | H20: 124 | I20: 1726
G21: =G20/I20 -> 0.92815759 | H21: =H20/I20 -> 0.07184241
F25: Reporting Status | G25: PG
F26: Nodal Point Table
F27: Grouping | G27: Count of Name
F28: Kelambakkam | G28: 17
F29: Sholinganallur | G29: 28
F30: Siruseri | G30: 1551
F31: Vandalur | G31: 1
F32: Velachery | G32: 5
F33: Grand Total | G33: 1602
F41: Gender | G41: PG | H41: Home | I41: Total | J41: Percentage | M41: Nodal Point | N41: Count | P41: Zone | Q41: Sep 2026 | R41: Oct 2026 | S41: Nov 2026 | T41: Dec 2026 | U41: Total | W41: Zone/Release month | X41: Sep 2026 | Z41: Sep 2026 Total | AA41: Oct 2026 | AC41: Oct 2026 Total | AD41: Nov 2026 | AF41: Nov 2026 Total | AG41: Dec 2026 | AI41: Dec 2026 Total | AJ41: Grand Total
F42: Female | G42: 681 | H42: 54 | I42: 735 | J42: =I42/I44 -> 0.42584009 | M42: Kelambakkam | N42: 17 | P42: Amber | Q42: 8 | R42: 1 | S42: 3 | T42: 6 | U42: 18 | X42: Female | Y42: Male | AA42: Female | AB42: Male | AD42: Female | AE42: Male | AG42: Female | AH42: Male
F43: Male | G43: 921 | H43: 70 | I43: 991 | J43: =I43/I44 -> 0.57415991 | M43: Sholinganallur | N43: 28 | P43: Red | Q43: 319 | R43: 421 | S43: 394 | T43: 450 | U43: 1584 | W43: Amber | X43: 4 | Y43: 4 | Z43: 8 | AB43: 1 | AC43: 1 | AE43: 3 | AF43: 3 | AG43: 4 | AH43: 2 | AI43: 6 | AJ43: 18
F44: Total | G44: 1602 | H44: 124 | I44: 1726 | J44: 1 | M44: Siruseri | N44: 1551 | P44: Total | Q44: 327 | R44: 422 | S44: 397 | T44: 456 | U44: 1602 | W44: Red | X44: 134 | Y44: 185 | Z44: 319 | AA44: 169 | AB44: 252 | AC44: 421 | AD44: 176 | AE44: 218 | AF44: 394 | AG44: 194 | AH44: 256 | AI44: 450 | AJ44: 1584
F45: Percentage | G45: =G44/I44 -> 0.92815759 | H45: =H44/I44 -> 0.07184241 | I45: 1 | J45: NA | M45: Vandalur | N45: 1 | W45: Grand Total | X45: 138 | Y45: 189 | Z45: 327 | AA45: 169 | AB45: 253 | AC45: 422 | AD45: 176 | AE45: 221 | AF45: 397 | AG45: 198 | AH45: 258 | AI45: 456 | AJ45: 1602
G46: ` | M46: Velachery | N46: 5
M47: Total | N47: 1602

Sheet Base
A1: Associate Id | B1: Name | C1: DOJ | D1: Gender | E1: Joiners Type | F1: Joining Location | G1: Cohort Code | H1: Coach Name | I1: Revised End date | J1: Release Month | K1: Final Status | L1: Reporting Status | M1: Reporting from | N1: PG Name | O1: Floor | P1: Relatives in Chennai | Q1: Nearby location to board if in case any Emergency: | R1: Grouping | S1: Zone
A2: 2529534 | B2: =VLOOKUP(A2,File!$A:$J,2,FALSE) -> Dharanakumar V | C2: =VLOOKUP(A2,File!$A:$J,5,FALSE) -> 46245 | D2: =VLOOKUP(A2,File!$A:$J,3,FALSE) -> Male | E2: =VLOOKUP(A2,File!$A:$J,4,FALSE) -> FTE | F2: =VLOOKUP(A2,File!$A:$J,6,FALSE) -> Chennai | G2: =VLOOKUP(A2,File!$A:$J,7,FALSE) -> CIS26MCPT025 | H2: =VLOOKUP(A2,File!$A:$J,8,FALSE) -> Vignesh S | I2: =VLOOKUP(A2,File!$A:$J,9,FALSE) -> 46359 | J2: =VLOOKUP(A2,File!$A:$K,11,FALSE) -> Dec 2026 | K2: =VLOOKUP(A2,File!$A:$K,10,FALSE) -> In-Training | L2: Home | M2: =VLOOKUP(A2,Response!$A:$M,7,) -> Permanent Residence (House/Home) | N2: =VLOOKUP(A2,Response!$A:$M,8,) -> - | O2: =VLOOKUP(A2,Response!$A:$M,10,) -> 1 | P2: =VLOOKUP(A2,Response!$A:$M,12,) -> Yes | Q2: =VLOOKUP(A2,Response!$A:$M,11,) -> Karapakkam | S2: N/A
A3: 2531975 | B3: =VLOOKUP(A3,File!$A:$J,2,FALSE) -> Roslin Nihara M | C3: =VLOOKUP(A3,File!$A:$J,5,FALSE) -> 46254 | D3: =VLOOKUP(A3,File!$A:$J,3,FALSE) -> Female | E3: =VLOOKUP(A3,File!$A:$J,4,FALSE) -> FTE | F3: =VLOOKUP(A3,File!$A:$J,6,FALSE) -> Chennai | G3: =VLOOKUP(A3,File!$A:$J,7,FALSE) -> EPS26OSP011 | H3: =VLOOKUP(A3,File!$A:$J,8,FALSE) -> Gayathri Ramachandran | I3: =VLOOKUP(A3,File!$A:$J,9,FALSE) | J3: Dec 2026 | K3: =VLOOKUP(A3,File!$A:$K,10,FALSE) -> Training - ON Hold | L3: Home | M3: =VLOOKUP(A3,Response!$A:$M,7,) -> Permanent Residence (House/Home) | N3: =VLOOKUP(A3,Response!$A:$M,8,) | O3: =VLOOKUP(A3,Response!$A:$M,10,) -> GF | P3: =VLOOKUP(A3,Response!$A:$M,12,) -> Yes | Q3: =VLOOKUP(A3,Response!$A:$M,11,) -> RAMAPURAM | S3: N/A
A4: 2530216 | B4: =VLOOKUP(A4,File!$A:$J,2,FALSE) -> Lipika C | C4: =VLOOKUP(A4,File!$A:$J,5,FALSE) -> 46247 | D4: =VLOOKUP(A4,File!$A:$J,3,FALSE) -> Female | E4: =VLOOKUP(A4,File!$A:$J,4,FALSE) -> FTE | F4: =VLOOKUP(A4,File!$A:$J,6,FALSE) -> Chennai | G4: =VLOOKUP(A4,File!$A:$J,7,FALSE) -> EPS26OSPPRO001 | H4: =VLOOKUP(A4,File!$A:$J,8,FALSE) -> Gayathri Ramachandran | I4: =VLOOKUP(A4,File!$A:$J,9,FALSE) -> 46363 | J4: =VLOOKUP(A4,File!$A:$K,11,FALSE) -> Dec 2026 | K4: =VLOOKUP(A4,File!$A:$K,10,FALSE) -> In-Training | L4: PG | M4: =VLOOKUP(A4,Response!$A:$M,7,) -> PG (Paying Guest) | N4: =VLOOKUP(A4,Response!$A:$M,8,) -> Aura Nest Pg For Ladies | O4: =VLOOKUP(A4,Response!$A:$M,10,) -> 2 | P4: =VLOOKUP(A4,Response!$A:$M,12,) -> Yes | Q4: =VLOOKUP(A4,Response!$A:$M,11,) -> Egattur | R4: Siruseri | S4: Red
A5: 2521623 | B5: =VLOOKUP(A5,File!$A:$J,2,FALSE) -> Sana Sumera | C5: =VLOOKUP(A5,File!$A:$J,5,FALSE) -> 46212 | D5: =VLOOKUP(A5,File!$A:$J,3,FALSE) -> Female | E5: =VLOOKUP(A5,File!$A:$J,4,FALSE) -> FTE | F5: =VLOOKUP(A5,File!$A:$J,6,FALSE) -> Chennai | G5: =VLOOKUP(A5,File!$A:$J,7,FALSE) -> QEA26QEPT023 | H5: =VLOOKUP(A5,File!$A:$J,8,FALSE) -> Sweta Thoppil | I5: =VLOOKUP(A5,File!$A:$J,9,FALSE) -> 46314 | J5: =VLOOKUP(A5,File!$A:$K,11,FALSE) -> Oct 2026 | K5: =VLOOKUP(A5,File!$A:$K,10,FALSE) -> In-Training | L5: PG | M5: =VLOOKUP(A5,Response!$A:$M,7,) -> Hostel | N5: =VLOOKUP(A5,Response!$A:$M,8,) -> Aura Nest Pg For Ladies | O5: =VLOOKUP(A5,Response!$A:$M,10,) -> 2 | P5: =VLOOKUP(A5,Response!$A:$M,12,) -> No | Q5: =VLOOKUP(A5,Response!$A:$M,11,) -> Egattur | R5: Siruseri | S5: Red
A6: 2521079 | B6: =VLOOKUP(A6,File!$A:$J,2,FALSE) -> Nalamothu Rishith | C6: =VLOOKUP(A6,File!$A:$J,5,FALSE) -> 46210 | D6: =VLOOKUP(A6,File!$A:$J,3,FALSE) -> Male | E6: =VLOOKUP(A6,File!$A:$J,4,FALSE) -> FTE | F6: =VLOOKUP(A6,File!$A:$J,6,FALSE) -> Chennai | G6: =VLOOKUP(A6,File!$A:$J,7,FALSE) -> CIS26SN001 | H6: =VLOOKUP(A6,File!$A:$J,8,FALSE) -> Ashiya Begam S | I6: =VLOOKUP(A6,File!$A:$J,9,FALSE) -> 46281 | J6: =VLOOKUP(A6,File!$A:$K,11,FALSE) -> Sep 2026 | K6: =VLOOKUP(A6,File!$A:$K,10,FALSE) -> In-Training | L6: PG | M6: =VLOOKUP(A6,Response!$A:$M,7,) -> PG (Paying Guest) | N6: =VLOOKUP(A6,Response!$A:$M,8,) -> CNR GENTS PG BRANCH-1 | O6: =VLOOKUP(A6,Response!$A:$M,10,) -> 3 | P6: =VLOOKUP(A6,Response!$A:$M,12,) -> No | Q6: =VLOOKUP(A6,Response!$A:$M,11,) -> Siruseri | R6: Siruseri | S6: Red
A7: 2507506 | B7: =VLOOKUP(A7,File!$A:$J,2,FALSE) -> Rudra Naga Gani Varalakshmi Harika | C7: =VLOOKUP(A7,File!$A:$J,5,FALSE) -> 46142 | D7: =VLOOKUP(A7,File!$A:$J,3,FALSE) -> Female | E7: =VLOOKUP(A7,File!$A:$J,4,FALSE) -> FTE | F7: =VLOOKUP(A7,File!$A:$J,6,FALSE) -> Chennai | G7: =VLOOKUP(A7,File!$A:$J,7,FALSE) -> ADM26MF009 | H7: =VLOOKUP(A7,File!$A:$J,8,FALSE) -> Nithyakalyani Muthukumar | I7: =VLOOKUP(A7,File!$A:$J,9,FALSE) -> 46274 | J7: =VLOOKUP(A7,File!$A:$K,11,FALSE) -> Sep 2026 | K7: =VLOOKUP(A7,File!$A:$K,10,FALSE) -> In-Training-Remedial | L7: PG | M7: =VLOOKUP(A7,Response!$A:$M,7,) -> PG (Paying Guest) | N7: =VLOOKUP(A7,Response!$A:$M,8,) -> Dheekshith Ladies Pg. | O7: =VLOOKUP(A7,Response!$A:$M,10,) -> 2 | P7: =VLOOKUP(A7,Response!$A:$M,12,) -> No | Q7: =VLOOKUP(A7,Response!$A:$M,11,) -> Egattur | R7: Siruseri | S7: Red
A8: 2485951 | B8: =VLOOKUP(A8,File!$A:$J,2,FALSE) -> Chaitanya,Prakash Ghatbandhe | C8: =VLOOKUP(A8,File!$A:$J,5,FALSE) -> 46072 | D8: =VLOOKUP(A8,File!$A:$J,3,FALSE) -> Male | E8: =VLOOKUP(A8,File!$A:$J,4,FALSE) -> FTE | F8: =VLOOKUP(A8,File!$A:$J,6,FALSE) -> Chennai | G8: =VLOOKUP(A8,File!$A:$J,7,FALSE) -> QEA26QEPT023 | H8: =VLOOKUP(A8,File!$A:$J,8,FALSE) -> Sweta Thoppil | I8: =VLOOKUP(A8,File!$A:$J,9,FALSE) -> 46314 | J8: =VLOOKUP(A8,File!$A:$K,11,FALSE) -> Oct 2026 | K8: =VLOOKUP(A8,File!$A:$K,10,FALSE) -> In-Training | L8: PG | M8: =VLOOKUP(A8,Response!$A:$M,7,) -> PG (Paying Guest) | N8: =VLOOKUP(A8,Response!$A:$M,8,) -> Pasanga Paradise PG - Branch 1, Egattur | O8: =VLOOKUP(A8,Response!$A:$M,10,) -> 4 | P8: =VLOOKUP(A8,Response!$A:$M,12,) -> No | Q8: =VLOOKUP(A8,Response!$A:$M,11,) -> Egattur | R8: Siruseri | S8: Red
A9: 2521631 | B9: =VLOOKUP(A9,File!$A:$J,2,FALSE) -> B Likith Vardhan Reddy | C9: =VLOOKUP(A9,File!$A:$J,5,FALSE) -> 46212 | D9: =VLOOKUP(A9,File!$A:$J,3,FALSE) -> Male | E9: =VLOOKUP(A9,File!$A:$J,4,FALSE) -> FTE | F9: =VLOOKUP(A9,File!$A:$J,6,FALSE) -> Chennai | G9: =VLOOKUP(A9,File!$A:$J,7,FALSE) -> QEA26QEPT023 | H9: =VLOOKUP(A9,File!$A:$J,8,FALSE) -> Sweta Thoppil | I9: =VLOOKUP(A9,File!$A:$J,9,FALSE) -> 46314 | J9: =VLOOKUP(A9,File!$A:$K,11,FALSE) -> Oct 2026 | K9: =VLOOKUP(A9,File!$A:$K,10,FALSE) -> In-Training | L9: PG | M9: =VLOOKUP(A9,Response!$A:$M,7,) -> PG (Paying Guest) | N9: =VLOOKUP(A9,Response!$A:$M,8,) -> S S Gents Pg | O9: =VLOOKUP(A9,Response!$A:$M,10,) -> 4 | P9: =VLOOKUP(A9,Response!$A:$M,12,) -> No | Q9: =VLOOKUP(A9,Response!$A:$M,11,) -> Siruseri | R9: Siruseri | S9: Red
A10: 2523372 | B10: =VLOOKUP(A10,File!$A:$J,2,FALSE) -> Aditya Prabhakar Deshmukh | C10: =VLOOKUP(A10,File!$A:$J,5,FALSE) -> 46219 | D10: =VLOOKUP(A10,File!$A:$J,3,FALSE) -> Male | E10: =VLOOKUP(A10,File!$A:$J,4,FALSE) -> FTE | F10: =VLOOKUP(A10,File!$A:$J,6,FALSE) -> Chennai | G10: =VLOOKUP(A10,File!$A:$J,7,FALSE) -> CS26CS009 | H10: =VLOOKUP(A10,File!$A:$J,8,FALSE) -> Laksiya Vijayendran | I10: =VLOOKUP(A10,File!$A:$J,9,FALSE) -> 46309 | J10: =VLOOKUP(A10,File!$A:$K,11,FALSE) -> Oct 2026 | K10: =VLOOKUP(A10,File!$A:$K,10,FALSE) -> In-Training | L10: PG | M10: =VLOOKUP(A10,Response!$A:$M,7,) -> PG (Paying Guest) | N10: =VLOOKUP(A10,Response!$A:$M,8,) -> Soma Mens Stay | O10: =VLOOKUP(A10,Response!$A:$M,10,) -> GF | P10: =VLOOKUP(A10,Response!$A:$M,12,) -> Yes | Q10: =VLOOKUP(A10,Response!$A:$M,11,) -> Siruseri | R10: Siruseri | S10: Red
A11: 2533210 | B11: =VLOOKUP(A11,File!$A:$J,2,FALSE) -> Varsha Kodadi | C11: =VLOOKUP(A11,File!$A:$J,5,FALSE) -> 46259 | D11: =VLOOKUP(A11,File!$A:$J,3,FALSE) -> Female | E11: =VLOOKUP(A11,File!$A:$J,4,FALSE) -> FTE | F11: =VLOOKUP(A11,File!$A:$J,6,FALSE) -> Chennai | G11: =VLOOKUP(A11,File!$A:$J,7,FALSE) -> CIS26AT007 | H11: =VLOOKUP(A11,File!$A:$J,8,FALSE) -> Uma Venkatachalam | I11: =VLOOKUP(A11,File!$A:$J,9,FALSE) -> 46365 | J11: =VLOOKUP(A11,File!$A:$K,11,FALSE) -> Dec 2026 | K11: =VLOOKUP(A11,File!$A:$K,10,FALSE) -> In-Training | L11: PG | M11: =VLOOKUP(A11,Response!$A:$M,7,) -> PG (Paying Guest) | N11: =VLOOKUP(A11,Response!$A:$M,8,) -> UniQ PG | O11: =VLOOKUP(A11,Response!$A:$M,10,) -> 2 | P11: =VLOOKUP(A11,Response!$A:$M,12,) -> No | Q11: =VLOOKUP(A11,Response!$A:$M,11,) -> Egattur | R11: Siruseri | S11: Red
A12: 2531306 | B12: =VLOOKUP(A12,File!$A:$J,2,FALSE) -> Nishanthi K | C12: =VLOOKUP(A12,File!$A:$J,5,FALSE) -> 46252 | D12: =VLOOKUP(A12,File!$A:$J,3,FALSE) -> Female | E12: =VLOOKUP(A12,File!$A:$J,4,FALSE) -> FTE | F12: =VLOOKUP(A12,File!$A:$J,6,FALSE) -> Chennai | G12: =VLOOKUP(A12,File!$A:$J,7,FALSE) -> CIS26DWP030 | H12: =VLOOKUP(A12,File!$A:$J,8,FALSE) -> Prokriti Biswas | I12: =VLOOKUP(A12,File!$A:$J,9,FALSE) -> 46324 | J12: =VLOOKUP(A12,File!$A:$K,11,FALSE) -> Oct 2026 | K12: =VLOOKUP(A12,File!$A:$K,10,FALSE) -> In-Training | L12: Home | M12: =VLOOKUP(A12,Response!$A:$M,7,) -> Permanent Residence (House/Home) | N12: =VLOOKUP(A12,Response!$A:$M,8,) -> "X" Block | O12: =VLOOKUP(A12,Response!$A:$M,10,) -> 1 | P12: =VLOOKUP(A12,Response!$A:$M,12,) -> Yes | Q12: =VLOOKUP(A12,Response!$A:$M,11,) -> Ashok Piller | S12: N/A
A13: 2521700 | B13: =VLOOKUP(A13,File!$A:$J,2,FALSE) -> Megha Roy | C13: =VLOOKUP(A13,File!$A:$J,5,FALSE) -> 46212 | D13: =VLOOKUP(A13,File!$A:$J,3,FALSE) -> Female | E13: =VLOOKUP(A13,File!$A:$J,4,FALSE) -> FTE | F13: =VLOOKUP(A13,File!$A:$J,6,FALSE) -> Chennai | G13: =VLOOKUP(A13,File!$A:$J,7,FALSE) -> QEA26QEPT023 | H13: =VLOOKUP(A13,File!$A:$J,8,FALSE) -> Sweta Thoppil | I13: =VLOOKUP(A13,File!$A:$J,9,FALSE) -> 46314 | J13: =VLOOKUP(A13,File!$A:$K,11,FALSE) -> Oct 2026 | K13: =VLOOKUP(A13,File!$A:$K,10,FALSE) -> In-Training | L13: PG | M13: =VLOOKUP(A13,Response!$A:$M,7,) -> PG (Paying Guest) | N13: =VLOOKUP(A13,Response!$A:$M,8,) -> Sns Pg For Ladies | O13: =VLOOKUP(A13,Response!$A:$M,10,) -> 3 | P13: =VLOOKUP(A13,Response!$A:$M,12,) -> No | Q13: =VLOOKUP(A13,Response!$A:$M,11,) -> Egattur | R13: Siruseri | S13: Red
A14: 2521297 | B14: =VLOOKUP(A14,File!$A:$J,2,FALSE) -> Buela Sindhu Thirumalasetty | C14: =VLOOKUP(A14,File!$A:$J,5,FALSE) -> 46210 | D14: =VLOOKUP(A14,File!$A:$J,3,FALSE) -> Female | E14: =VLOOKUP(A14,File!$A:$J,4,FALSE) -> FTE | F14: =VLOOKUP(A14,File!$A:$J,6,FALSE) -> Chennai | G14: =VLOOKUP(A14,File!$A:$J,7,FALSE) -> SNBG26SN002 | H14: =VLOOKUP(A14,File!$A:$J,8,FALSE) -> Lawrance M | I14: =VLOOKUP(A14,File!$A:$J,9,FALSE) -> 46281 | J14: =VLOOKUP(A14,File!$A:$K,11,FALSE) -> Sep 2026 | K14: =VLOOKUP(A14,File!$A:$K,10,FALSE) -> In-Training | L14: PG | M14: =VLOOKUP(A14,Response!$A:$M,7,) -> PG (Paying Guest) | N14: =VLOOKUP(A14,Response!$A:$M,8,) -> 1/210a, Dr Ambedkar St, Egattur, Chennai, Tamil Nadu 600130 | O14: =VLOOKUP(A14,Response!$A:$M,10,) -> 3 | P14: =VLOOKUP(A14,Response!$A:$M,12,) -> No | Q14: =VLOOKUP(A14,Response!$A:$M,11,) -> Egattur | R14: Siruseri | S14: Red
A15: 2523419 | B15: =VLOOKUP(A15,File!$A:$J,2,FALSE) -> Uzma Jabeen Syed Raza Ali | C15: =VLOOKUP(A15,File!$A:$J,5,FALSE) -> 46219 | D15: =VLOOKUP(A15,File!$A:$J,3,FALSE) -> Female | E15: =VLOOKUP(A15,File!$A:$J,4,FALSE) -> FTE | F15: =VLOOKUP(A15,File!$A:$J,6,FALSE) -> Chennai | G15: =VLOOKUP(A15,File!$A:$J,7,FALSE) -> PG26JFR004 | H15: =VLOOKUP(A15,File!$A:$J,8,FALSE) -> Thomas Naveen. J | I15: =VLOOKUP(A15,File!$A:$J,9,FALSE) -> 46342 | J15: =VLOOKUP(A15,File!$A:$K,11,FALSE) -> Nov 2026 | K15: =VLOOKUP(A15,File!$A:$K,10,FALSE) -> In-Training | L15: PG | M15: =VLOOKUP(A15,Response!$A:$M,7,) -> PG (Paying Guest) | N15: =VLOOKUP(A15,Response!$A:$M,8,) -> 1/210a, SRS Luxury PG for Ladies Branch 2, Dr. Ambedkar Street, Egattur | O15: =VLOOKUP(A15,Response!$A:$M,10,) -> 2 | P15: =VLOOKUP(A15,Response!$A:$M,12,) -> No | Q15: =VLOOKUP(A15,Response!$A:$M,11,) -> Egattur | R15: Siruseri | S15: Red
A16: 2523379 | B16: =VLOOKUP(A16,File!$A:$J,2,FALSE) -> Abilash A | C16: =VLOOKUP(A16,File!$A:$J,5,FALSE) -> 46219 | D16: =VLOOKUP(A16,File!$A:$J,3,FALSE) -> Male | E16: =VLOOKUP(A16,File!$A:$J,4,FALSE) -> FTE | F16: =VLOOKUP(A16,File!$A:$J,6,FALSE) -> Chennai | G16: =VLOOKUP(A16,File!$A:$J,7,FALSE) -> PG26JFR004 | H16: =VLOOKUP(A16,File!$A:$J,8,FALSE) -> Thomas Naveen. J | I16: =VLOOKUP(A16,File!$A:$J,9,FALSE) -> 46342 | J16: =VLOOKUP(A16,File!$A:$K,11,FALSE) -> Nov 2026 | K16: =VLOOKUP(A16,File!$A:$K,10,FALSE) -> In-Training | L16: Home | M16: =VLOOKUP(A16,Response!$A:$M,7,) -> Rented House/Apartment | N16: =VLOOKUP(A16,Response!$A:$M,8,) -> 1/749, Maruthi Nagar, Perungudi, Chennai 600096 | O16: =VLOOKUP(A16,Response!$A:$M,10,) -> 1 | P16: =VLOOKUP(A16,Response!$A:$M,12,) -> Yes | Q16: =VLOOKUP(A16,Response!$A:$M,11,) -> Thoraipakkam | R16: Sholinganallur | S16: N/A
A17: 2521836 | B17: =VLOOKUP(A17,File!$A:$J,2,FALSE) -> Karan Saxena | C17: =VLOOKUP(A17,File!$A:$J,5,FALSE) -> 46212 | D17: =VLOOKUP(A17,File!$A:$J,3,FALSE) -> Male | E17: =VLOOKUP(A17,File!$A:$J,4,FALSE) -> FTE | F17: =VLOOKUP(A17,File!$A:$J,6,FALSE) -> Chennai | G17: =VLOOKUP(A17,File!$A:$J,7,FALSE) -> QEA26SD001 | H17: =VLOOKUP(A17,File!$A:$J,8,FALSE) -> Ajiesya D P | I17: =VLOOKUP(A17,File!$A:$J,9,FALSE) -> 46329 | J17: =VLOOKUP(A17,File!$A:$K,11,FALSE) -> Nov 2026 | K17: =VLOOKUP(A17,File!$A:$K,10,FALSE) -> In-Training | L17: Home | M17: =VLOOKUP(A17,Response!$A:$M,7,) -> Relatives Residence | N17: =VLOOKUP(A17,Response!$A:$M,8,) -> 102B Greenwood, Hiranandani, Egattur | O17: =VLOOKUP(A17,Response!$A:$M,10,) -> 1 | P17: =VLOOKUP(A17,Response!$A:$M,12,) -> Yes | Q17: =VLOOKUP(A17,Response!$A:$M,11,) -> Egattur | R17: Siruseri | S17: N/A
A18: 2532952 | B18: =VLOOKUP(A18,File!$A:$J,2,FALSE) -> Manendra Mallakuppam | C18: =VLOOKUP(A18,File!$A:$J,5,FALSE) -> 46259 | D18: =VLOOKUP(A18,File!$A:$J,3,FALSE) -> Male | E18: =VLOOKUP(A18,File!$A:$J,4,FALSE) -> FTE | F18: =VLOOKUP(A18,File!$A:$J,6,FALSE) -> Chennai | G18: =VLOOKUP(A18,File!$A:$J,7,FALSE) -> CIS26MBG004 | H18: =VLOOKUP(A18,File!$A:$J,8,FALSE) -> Kishorekumar P | I18: =VLOOKUP(A18,File!$A:$J,9,FALSE) -> 46367 | J18: =VLOOKUP(A18,File!$A:$K,11,FALSE) -> Dec 2026 | K18: =VLOOKUP(A18,File!$A:$K,10,FALSE) -> In-Training | L18: PG | M18: =VLOOKUP(A18,Response!$A:$M,7,) -> PG (Paying Guest) | N18: =VLOOKUP(A18,Response!$A:$M,8,) -> 105, Happy Homes Mens PG city park, Egatoor, Siruseri, Tamil Nadu 603103 | O18: =VLOOKUP(A18,Response!$A:$M,10,) -> 1 | P18: =VLOOKUP(A18,Response!$A:$M,12,) -> No | Q18: =VLOOKUP(A18,Response!$A:$M,11,) -> Egattur | R18: Siruseri | S18: Red
A19: 2529576 | B19: =VLOOKUP(A19,File!$A:$J,2,FALSE) -> Tharun B | C19: =VLOOKUP(A19,File!$A:$J,5,FALSE) -> 46245 | D19: =VLOOKUP(A19,File!$A:$J,3,FALSE) -> Male | E19: =VLOOKUP(A19,File!$A:$J,4,FALSE) -> FTE | F19: =VLOOKUP(A19,File!$A:$J,6,FALSE) -> Chennai | G19: =VLOOKUP(A19,File!$A:$J,7,FALSE) -> CIS26MCPT024 | H19: =VLOOKUP(A19,File!$A:$J,8,FALSE) -> Ashiya Begam S | I19: =VLOOKUP(A19,File!$A:$J,9,FALSE) -> 46359 | J19: =VLOOKUP(A19,File!$A:$K,11,FALSE) -> Dec 2026 | K19: =VLOOKUP(A19,File!$A:$K,10,FALSE) -> In-Training | L19: Home | M19: =VLOOKUP(A19,Response!$A:$M,7,) -> Rented House/Apartment | N19: =VLOOKUP(A19,Response!$A:$M,8,) -> 12/14 Rama rao garden 1st street royapettah chennai-14 | O19: =VLOOKUP(A19,Response!$A:$M,10,) -> GF | P19: =VLOOKUP(A19,Response!$A:$M,12,) -> Yes | Q19: =VLOOKUP(A19,Response!$A:$M,11,) -> Royapettah | R19: Central | S19: Amber
A20: 2521188 | B20: =VLOOKUP(A20,File!$A:$J,2,FALSE) -> Meghana S | C20: =VLOOKUP(A20,File!$A:$J,5,FALSE) -> 46210 | D20: =VLOOKUP(A20,File!$A:$J,3,FALSE) -> Female | E20: =VLOOKUP(A20,File!$A:$J,4,FALSE) -> FTE | F20: =VLOOKUP(A20,File!$A:$J,6,FALSE) -> Chennai | G20: =VLOOKUP(A20,File!$A:$J,7,FALSE) -> HPC26DN005 | H20: =VLOOKUP(A20,File!$A:$J,8,FALSE) -> Viveka Preethi | I20: =VLOOKUP(A20,File!$A:$J,9,FALSE) -> 46296 | J20: =VLOOKUP(A20,File!$A:$K,11,FALSE) -> Oct 2026 | K20: =VLOOKUP(A20,File!$A:$K,10,FALSE) -> In-Training | L20: Home | M20: =VLOOKUP(A20,Response!$A:$M,7,) -> Rented House/Apartment | N20: =VLOOKUP(A20,Response!$A:$M,8,) -> 1-285, Sonachalam street, Rajiv Gandhi salai, OMR, Chennai-600130 | O20: =VLOOKUP(A20,Response!$A:$M,10,) -> 2 | P20: =VLOOKUP(A20,Response!$A:$M,12,) -> No | Q20: =VLOOKUP(A20,Response!$A:$M,11,) -> Navalur | R20: Siruseri | S20: N/A
A21: 2523447 | B21: =VLOOKUP(A21,File!$A:$J,2,FALSE) -> Saravanan A | C21: =VLOOKUP(A21,File!$A:$J,5,FALSE) -> 46219 | D21: =VLOOKUP(A21,File!$A:$J,3,FALSE) -> Male | E21: =VLOOKUP(A21,File!$A:$J,4,FALSE) -> FTE | F21: =VLOOKUP(A21,File!$A:$J,6,FALSE) -> Chennai | G21: =VLOOKUP(A21,File!$A:$J,7,FALSE) -> CS26CS010 | H21: =VLOOKUP(A21,File!$A:$J,8,FALSE) -> Laksiya Vijayendran | I21: =VLOOKUP(A21,File!$A:$J,9,FALSE) -> 46314 | J21: =VLOOKUP(A21,File!$A:$K,11,FALSE) -> Oct 2026 | K21: =VLOOKUP(A21,File!$A:$K,10,FALSE) -> In-Training | L21: PG | M21: =VLOOKUP(A21,Response!$A:$M,7,) -> PG (Paying Guest) | N21: =VLOOKUP(A21,Response!$A:$M,8,) -> 13 A, Narayanan Gents PG, Srivijayaganapathy nagar, mayana salai, navalur - 600130 | O21: =VLOOKUP(A21,Response!$A:$M,10,) -> 3 | P21: =VLOOKUP(A21,Response!$A:$M,12,) -> No | Q21: =VLOOKUP(A21,Response!$A:$M,11,) -> Navalur | R21: Siruseri | S21: Red
A22: 2523416 | B22: =VLOOKUP(A22,File!$A:$J,2,FALSE) -> Balakumaran Bommudurai | C22: =VLOOKUP(A22,File!$A:$J,5,FALSE) -> 46219 | D22: =VLOOKUP(A22,File!$A:$J,3,FALSE) -> Male | E22: =VLOOKUP(A22,File!$A:$J,4,FALSE) -> FTE | F22: =VLOOKUP(A22,File!$A:$J,6,FALSE) -> Chennai | G22: =VLOOKUP(A22,File!$A:$J,7,FALSE) -> CS26CS009 | H22: =VLOOKUP(A22,File!$A:$J,8,FALSE) -> Laksiya Vijayendran | I22: =VLOOKUP(A22,File!$A:$J,9,FALSE) -> 46309 | J22: =VLOOKUP(A22,File!$A:$K,11,FALSE) -> Oct 2026 | K22: =VLOOKUP(A22,File!$A:$K,10,FALSE) -> In-Training | L22: Home | M22: =VLOOKUP(A22,Response!$A:$M,7,) -> Rented House/Apartment | N22: =VLOOKUP(A22,Response!$A:$M,8,) -> 14 Valluvar high road ,subash nagar,chromepet,600044 | O22: =VLOOKUP(A22,Response!$A:$M,10,) -> 1 | P22: =VLOOKUP(A22,Response!$A:$M,12,) -> Yes | Q22: =VLOOKUP(A22,Response!$A:$M,11,) -> Chromepet | R22: Thambaram | S22: N/A
A23: 2521255 | B23: =VLOOKUP(A23,File!$A:$J,2,FALSE) -> Vikil Reddy Vangala | C23: =VLOOKUP(A23,File!$A:$J,5,FALSE) -> 46210 | D23: =VLOOKUP(A23,File!$A:$J,3,FALSE) -> Male | E23: =VLOOKUP(A23,File!$A:$J,4,FALSE) -> FTE | F23: =VLOOKUP(A23,File!$A:$J,6,FALSE) -> Chennai | G23: =VLOOKUP(A23,File!$A:$J,7,FALSE) -> CS26CS007 | H23: =VLOOKUP(A23,File!$A:$J,8,FALSE) -> Lawrance M | I23: =VLOOKUP(A23,File!$A:$J,9,FALSE) -> 46272 | J23: =VLOOKUP(A23,File!$A:$K,11,FALSE) -> Sep 2026 | K23: =VLOOKUP(A23,File!$A:$K,10,FALSE) -> In-Training | L23: PG | M23: =VLOOKUP(A23,Response!$A:$M,7,) -> PG (Paying Guest) | N23: =VLOOKUP(A23,Response!$A:$M,8,) -> 1st Left , Sipcot IT park , city park layout, Plot no - 56P, Siruseri , Egattur , Tamilnadu 603103 | O23: =VLOOKUP(A23,Response!$A:$M,10,) -> 1 | P23: =VLOOKUP(A23,Response!$A:$M,12,) -> No | Q23: =VLOOKUP(A23,Response!$A:$M,11,) -> Siruseri | R23: Siruseri | S23: Red
A24: 2532911 | B24: =VLOOKUP(A24,File!$A:$J,2,FALSE) -> Mokshith Billakanti | C24: =VLOOKUP(A24,File!$A:$J,5,FALSE) -> 46259 | D24: =VLOOKUP(A24,File!$A:$J,3,FALSE) -> Male | E24: =VLOOKUP(A24,File!$A:$J,4,FALSE) -> FTE | F24: =VLOOKUP(A24,File!$A:$J,6,FALSE) -> Chennai | G24: =VLOOKUP(A24,File!$A:$J,7,FALSE) -> CIS26SN002 | H24: =VLOOKUP(A24,File!$A:$J,8,FALSE) -> Ashiya Begam S | I24: =VLOOKUP(A24,File!$A:$J,9,FALSE) -> 46358 | J24: =VLOOKUP(A24,File!$A:$K,11,FALSE) -> Dec 2026 | K24: =VLOOKUP(A24,File!$A:$K,10,FALSE) -> In-Training | L24: PG | M24: =VLOOKUP(A24,Response!$A:$M,7,) -> PG (Paying Guest) | N24: =VLOOKUP(A24,Response!$A:$M,8,) -> 1st Left, Sipcot It Park, City Park Layout, Plot No -56P, Siruseri, Egattur, TamilNadu 603103 | O24: =VLOOKUP(A24,Response!$A:$M,10,) -> 1 | P24: =VLOOKUP(A24,Response!$A:$M,12,) -> No | Q24: =VLOOKUP(A24,Response!$A:$M,11,) -> Siruseri | R24: Siruseri | S24: Red
... A33: 2524635 | B33: =VLOOKUP(A33,File!$A:$J,2,FALSE) -> Arunthava Raj A | C33: =VLOOKUP(A33,File!$A:$J,5,FALSE) -> 46224 | D33: =VLOOKUP(A33,File!$A:$J,3,FALSE) -> Male | E33: =VLOOKUP(A33,File!$A:$J,4,FALSE) -> FTE | F33: =VLOOKUP(A33,File!$A:$J,6,FALSE) -> Chennai | G33: =VLOOKUP(A33,File!$A:$J,7,FALSE) -> ADM26DFSA007 | H33: =VLOOKUP(A33,File!$A:$J,8,FALSE) -> Sweta Thoppil | I33: =VLOOKUP(A33,File!$A:$J,9,FALSE) -> 46336 | J33: =VLOOKUP(A33,File!$A:$K,11,FALSE) -> Nov 2026 | K33: =VLOOKUP(A33,File!$A:$K,10,FALSE) -> In-Training | L33: Home | M33: =VLOOKUP(A33,Response!$A:$M,7,) -> Rented House/Apartment | N33: =VLOOKUP(A33,Response!$A:$M,8,) -> 4/453, plot no 2 | O33: =VLOOKUP(A33,Response!$A:$M,10,) -> GF | P33: =VLOOKUP(A33,Response!$A:$M,12,) -> Yes | Q33: =VLOOKUP(A33,Response!$A:$M,11,) -> Thiruvanmiyur | R33: Thiruvanmiyur | S33: N/A
A34: 2519656 | B34: =VLOOKUP(A34,File!$A:$J,2,FALSE) -> Hajara Kamila M | C34: =VLOOKUP(A34,File!$A:$J,5,FALSE) -> 46205 | D34: =VLOOKUP(A34,File!$A:$J,3,FALSE) -> Female | E34: =VLOOKUP(A34,File!$A:$J,4,FALSE) -> FTE | F34: =VLOOKUP(A34,File!$A:$J,6,FALSE) -> Chennai | G34: =VLOOKUP(A34,File!$A:$J,7,FALSE) -> CIS26DWP021 | H34: =VLOOKUP(A34,File!$A:$J,8,FALSE) -> Laksiya Vijayendran | I34: =VLOOKUP(A34,File!$A:$J,9,FALSE) -> 46272 | J34: =VLOOKUP(A34,File!$A:$K,11,FALSE) -> Sep 2026 | K34: =VLOOKUP(A34,File!$A:$K,10,FALSE) -> In-Training | L34: Home | M34: =VLOOKUP(A34,Response!$A:$M,7,) -> Relatives Residence | N34: =VLOOKUP(A34,Response!$A:$M,8,) -> 42/78, 3rd main road, Venkateswara Nagar, Velachery. | O34: =VLOOKUP(A34,Response!$A:$M,10,) -> GF | P34: =VLOOKUP(A34,Response!$A:$M,12,) -> No | Q34: =VLOOKUP(A34,Response!$A:$M,11,) -> Velachery. | S34: N/A
A35: 2521118 | B35: =VLOOKUP(A35,File!$A:$J,2,FALSE) -> Sri Ram Sankar T S | C35: =VLOOKUP(A35,File!$A:$J,5,FALSE) -> 46210 | D35: =VLOOKUP(A35,File!$A:$J,3,FALSE) -> Male | E35: =VLOOKUP(A35,File!$A:$J,4,FALSE) -> FTE | F35: =VLOOKUP(A35,File!$A:$J,6,FALSE) -> Chennai | G35: =VLOOKUP(A35,File!$A:$J,7,FALSE) -> CIS26SN001 | H35: =VLOOKUP(A35,File!$A:$J,8,FALSE) -> Ashiya Begam S | I35: =VLOOKUP(A35,File!$A:$J,9,FALSE) -> 46303 | J35: =VLOOKUP(A35,File!$A:$K,11,FALSE) -> Oct 2026 | K35: =VLOOKUP(A35,File!$A:$K,10,FALSE) -> In-Training | L35: PG | M35: =VLOOKUP(A35,Response!$A:$M,7,) -> PG (Paying Guest) | N35: =VLOOKUP(A35,Response!$A:$M,8,) -> 4th Floor, Vishvas Professional Stays, Plot No 34B, City Park, Egattur, Chennai, Tamil Nadu - 603130. | O35: =VLOOKUP(A35,Response!$A:$M,10,) -> 4 | P35: =VLOOKUP(A35,Response!$A:$M,12,) -> Yes | Q35: =VLOOKUP(A35,Response!$A:$M,11,) -> Siruseri | R35: Siruseri | S35: Red
A36: 2529802 | B36: =VLOOKUP(A36,File!$A:$J,2,FALSE) -> Mulla Sai Nadha Swamy | C36: =VLOOKUP(A36,File!$A:$J,5,FALSE) -> 46245 | D36: =VLOOKUP(A36,File!$A:$J,3,FALSE) -> Male | E36: =VLOOKUP(A36,File!$A:$J,4,FALSE) -> FTE | F36: =VLOOKUP(A36,File!$A:$J,6,FALSE) -> Chennai | G36: =VLOOKUP(A36,File!$A:$J,7,FALSE) -> CIS26AZ001 | H36: =VLOOKUP(A36,File!$A:$J,8,FALSE) -> Ashiya Begam S | I36: =VLOOKUP(A36,File!$A:$J,9,FALSE) -> 46335 | J36: =VLOOKUP(A36,File!$A:$K,11,FALSE) -> Nov 2026 | K36: =VLOOKUP(A36,File!$A:$K,10,FALSE) -> In-Training | L36: PG | M36: =VLOOKUP(A36,Response!$A:$M,7,) -> PG (Paying Guest) | N36: =VLOOKUP(A36,Response!$A:$M,8,) -> 4th stree , Aadhilakshmi PG for gents ,Egattur, | O36: =VLOOKUP(A36,Response!$A:$M,10,) -> 4 | P36: =VLOOKUP(A36,Response!$A:$M,12,) -> No | Q36: =VLOOKUP(A36,Response!$A:$M,11,) -> Egattur | R36: Siruseri | S36: Red
A37: 2529606 | B37: =VLOOKUP(A37,File!$A:$J,2,FALSE) -> Mohamed Anish J | C37: =VLOOKUP(A37,File!$A:$J,5,FALSE) -> 46245 | D37: =VLOOKUP(A37,File!$A:$J,3,FALSE) -> Male | E37: =VLOOKUP(A37,File!$A:$J,4,FALSE) -> FTE | F37: =VLOOKUP(A37,File!$A:$J,6,FALSE) -> Chennai | G37: =VLOOKUP(A37,File!$A:$J,7,FALSE) -> CIS26MCPT021 | H37: =VLOOKUP(A37,File!$A:$J,8,FALSE) -> Uma Venkatachalam | I37: =VLOOKUP(A37,File!$A:$J,9,FALSE) -> 46364 | J37: =VLOOKUP(A37,File!$A:$K,11,FALSE) -> Dec 2026 | K37: =VLOOKUP(A37,File!$A:$K,10,FALSE) -> In-Training | L37: Home | M37: =VLOOKUP(A37,Response!$A:$M,7,) -> Relatives Residence | N37: =VLOOKUP(A37,Response!$A:$M,8,) -> 5/112 Annai Indira Nagar, Thoraipakkam ,Chennai | O37: =VLOOKUP(A37,Response!$A:$M,10,) -> GF | P37: =VLOOKUP(A37,Response!$A:$M,12,) -> Yes | Q37: =VLOOKUP(A37,Response!$A:$M,11,) -> Siruseri | R37: Siruseri | S37: N/A
A38: 2525028 | B38: =VLOOKUP(A38,File!$A:$J,2,FALSE) -> Sumit Vishwakarma | C38: =VLOOKUP(A38,File!$A:$J,5,FALSE) -> 46226 | D38: =VLOOKUP(A38,File!$A:$J,3,FALSE) -> Male | E38: =VLOOKUP(A38,File!$A:$J,4,FALSE) -> FTE | F38: =VLOOKUP(A38,File!$A:$J,6,FALSE) -> Chennai | G38: =VLOOKUP(A38,File!$A:$J,7,FALSE) -> ADM26ISMO010 | H38: =VLOOKUP(A38,File!$A:$J,8,FALSE) -> Thomas Naveen. J | I38: =VLOOKUP(A38,File!$A:$J,9,FALSE) -> 46301 | J38: =VLOOKUP(A38,File!$A:$K,11,FALSE) -> Oct 2026 | K38: =VLOOKUP(A38,File!$A:$K,10,FALSE) -> In-Training | L38: PG | M38: =VLOOKUP(A38,Response!$A:$M,7,) -> PG (Paying Guest) | N38: =VLOOKUP(A38,Response!$A:$M,8,) -> 503, Brospace Phoenix premium mens PG indra gandhi street navalur | O38: =VLOOKUP(A38,Response!$A:$M,10,) -> 5 | P38: =VLOOKUP(A38,Response!$A:$M,12,) -> Yes | Q38: =VLOOKUP(A38,Response!$A:$M,11,) -> Navalur | R38: Siruseri | S38: Red
A39: 2507421 | B39: =VLOOKUP(A39,File!$A:$J,2,FALSE) -> Sanjay Kumar E | C39: =VLOOKUP(A39,File!$A:$J,5,FALSE) -> 46142 | D39: =VLOOKUP(A39,File!$A:$J,3,FALSE) -> Male | E39: =VLOOKUP(A39,File!$A:$J,4,FALSE) -> FTE | F39: =VLOOKUP(A39,File!$A:$J,6,FALSE) -> Chennai | G39: =VLOOKUP(A39,File!$A:$J,7,FALSE) -> ISG26JSAAT002 | H39: =VLOOKUP(A39,File!$A:$J,8,FALSE) -> Ashiya Begam S | I39: =VLOOKUP(A39,File!$A:$J,9,FALSE) -> 46272 | J39: =VLOOKUP(A39,File!$A:$K,11,FALSE) -> Sep 2026 | K39: =VLOOKUP(A39,File!$A:$K,10,FALSE) -> In-Training-Remedial | L39: Home | M39: =VLOOKUP(A39,Response!$A:$M,7,) -> Permanent Residence (House/Home) | N39: =VLOOKUP(A39,Response!$A:$M,8,) -> 8A , manikandan 2nd street,porur | O39: =VLOOKUP(A39,Response!$A:$M,10,) -> GF | P39: =VLOOKUP(A39,Response!$A:$M,12,) -> Yes | Q39: =VLOOKUP(A39,Response!$A:$M,11,) -> porur | S39: N/A
A40: 2533081 | B40: =VLOOKUP(A40,File!$A:$J,2,FALSE) -> Guvvala Asreetha | C40: =VLOOKUP(A40,File!$A:$J,5,FALSE) -> 46259 | D40: =VLOOKUP(A40,File!$A:$J,3,FALSE) -> Female | E40: =VLOOKUP(A40,File!$A:$J,4,FALSE) -> FTE | F40: =VLOOKUP(A40,File!$A:$J,6,FALSE) -> Chennai | G40: =VLOOKUP(A40,File!$A:$J,7,FALSE) -> CIS26SN002 | H40: =VLOOKUP(A40,File!$A:$J,8,FALSE) -> Ashiya Begam S | I40: =VLOOKUP(A40,File!$A:$J,9,FALSE) -> 46358 | J40: =VLOOKUP(A40,File!$A:$K,11,FALSE) -> Dec 2026 | K40: =VLOOKUP(A40,File!$A:$K,10,FALSE) -> In-Training | L40: PG | M40: =VLOOKUP(A40,Response!$A:$M,7,) -> PG (Paying Guest) | N40: =VLOOKUP(A40,Response!$A:$M,8,) -> a | O40: =VLOOKUP(A40,Response!$A:$M,10,) -> 1 | P40: =VLOOKUP(A40,Response!$A:$M,12,) -> Yes | Q40: =VLOOKUP(A40,Response!$A:$M,11,) -> Siruseri | R40: Siruseri | S40: Red
A41: 2529597 | B41: =VLOOKUP(A41,File!$A:$J,2,FALSE) -> Kandula Siva Pratap | C41: =VLOOKUP(A41,File!$A:$J,5,FALSE) -> 46245 | D41: =VLOOKUP(A41,File!$A:$J,3,FALSE) -> Male | E41: =VLOOKUP(A41,File!$A:$J,4,FALSE) -> FTE | F41: =VLOOKUP(A41,File!$A:$J,6,FALSE) -> Chennai | G41: =VLOOKUP(A41,File!$A:$J,7,FALSE) -> CIS26MCPT026 | H41: =VLOOKUP(A41,File!$A:$J,8,FALSE) -> Mohamed Harish | I41: =VLOOKUP(A41,File!$A:$J,9,FALSE) -> 46364 | J41: =VLOOKUP(A41,File!$A:$K,11,FALSE) -> Dec 2026 | K41: =VLOOKUP(A41,File!$A:$K,10,FALSE) -> In-Training | L41: PG | M41: =VLOOKUP(A41,Response!$A:$M,7,) -> PG (Paying Guest) | N41: =VLOOKUP(A41,Response!$A:$M,8,) -> AADHI LAKSHMI PG FOR GENTS , Egattur | O41: =VLOOKUP(A41,Response!$A:$M,10,) -> 2 | P41: =VLOOKUP(A41,Response!$A:$M,12,) -> No | Q41: =VLOOKUP(A41,Response!$A:$M,11,) -> Egattur | R41: Siruseri | S41: Red
A42: 2531818 | B42: =VLOOKUP(A42,File!$A:$J,2,FALSE) -> Ashish Sriniwas Prasad | C42: =VLOOKUP(A42,File!$A:$J,5,FALSE) -> 46254 | D42: =VLOOKUP(A42,File!$A:$J,3,FALSE) -> Male | E42: =VLOOKUP(A42,File!$A:$J,4,FALSE) -> FTE | F42: =VLOOKUP(A42,File!$A:$J,6,FALSE) -> Chennai | G42: =VLOOKUP(A42,File!$A:$J,7,FALSE) -> CS26CS012 | H42: =VLOOKUP(A42,File!$A:$J,8,FALSE) -> Laksiya Vijayendran | I42: =VLOOKUP(A42,File!$A:$J,9,FALSE) -> 46343 | J42: =VLOOKUP(A42,File!$A:$K,11,FALSE) -> Nov 2026 | K42: =VLOOKUP(A42,File!$A:$K,10,FALSE) -> In-Training | L42: PG | M42: =VLOOKUP(A42,Response!$A:$M,7,) -> PG (Paying Guest) | N42: =VLOOKUP(A42,Response!$A:$M,8,) -> AADHI LAKSHMI PG FOR GENTS , Egattur | O42: =VLOOKUP(A42,Response!$A:$M,10,) -> 6 | P42: =VLOOKUP(A42,Response!$A:$M,12,) -> No | Q42: =VLOOKUP(A42,Response!$A:$M,11,) -> Siruseri | R42: Siruseri | S42: Red
A43: 2529630 | B43: =VLOOKUP(A43,File!$A:$J,2,FALSE) -> Prashant Dhanaji Narale | C43: =VLOOKUP(A43,File!$A:$J,5,FALSE) -> 46245 | D43: =VLOOKUP(A43,File!$A:$J,3,FALSE) -> Male | E43: =VLOOKUP(A43,File!$A:$J,4,FALSE) -> FTE | F43: =VLOOKUP(A43,File!$A:$J,6,FALSE) -> Chennai | G43: =VLOOKUP(A43,File!$A:$J,7,FALSE) -> CIS26MCPT024 | H43: =VLOOKUP(A43,File!$A:$J,8,FALSE) -> Ashiya Begam S | I43: =VLOOKUP(A43,File!$A:$J,9,FALSE) -> 46359 | J43: =VLOOKUP(A43,File!$A:$K,11,FALSE) -> Dec 2026 | K43: =VLOOKUP(A43,File!$A:$K,10,FALSE) -> In-Training | L43: PG | M43: =VLOOKUP(A43,Response!$A:$M,7,) -> PG (Paying Guest) | N43: =VLOOKUP(A43,Response!$A:$M,8,) -> AADHI LAKSHMI PG FOR GENTS , Egattur | O43: =VLOOKUP(A43,Response!$A:$M,10,) -> 1 | P43: =VLOOKUP(A43,Response!$A:$M,12,) -> No | Q43: =VLOOKUP(A43,Response!$A:$M,11,) -> Siruseri | R43: Siruseri | S43: Red
A44: 2533170 | B44: =VLOOKUP(A44,File!$A:$J,2,FALSE) -> Prem Sai Adigopula | C44: =VLOOKUP(A44,File!$A:$J,5,FALSE) -> 46259 | D44: =VLOOKUP(A44,File!$A:$J,3,FALSE) -> Male | E44: =VLOOKUP(A44,File!$A:$J,4,FALSE) -> FTE | F44: =VLOOKUP(A44,File!$A:$J,6,FALSE) -> Chennai | G44: =VLOOKUP(A44,File!$A:$J,7,FALSE) -> CIS26MBG006 | H44: =VLOOKUP(A44,File!$A:$J,8,FALSE) -> Angel Maria Faustina Gomez | I44: =VLOOKUP(A44,File!$A:$J,9,FALSE) -> 46367 | J44: =VLOOKUP(A44,File!$A:$K,11,FALSE) -> Dec 2026 | K44: =VLOOKUP(A44,File!$A:$K,10,FALSE) -> In-Training | L44: PG | M44: =VLOOKUP(A44,Response!$A:$M,7,) -> PG (Paying Guest) | N44: =VLOOKUP(A44,Response!$A:$M,8,) -> AADHI LAKSHMI PG FOR GENTS , Egattur | O44: =VLOOKUP(A44,Response!$A:$M,10,) -> 1 | P44: =VLOOKUP(A44,Response!$A:$M,12,) -> No | Q44: =VLOOKUP(A44,Response!$A:$M,11,) -> Siruseri | R44: Siruseri | S44: Red
A45: 2531848 | B45: =VLOOKUP(A45,File!$A:$J,2,FALSE) -> Jathin Kumar Sahu | C45: =VLOOKUP(A45,File!$A:$J,5,FALSE) -> 46254 | D45: =VLOOKUP(A45,File!$A:$J,3,FALSE) -> Male | E45: =VLOOKUP(A45,File!$A:$J,4,FALSE) -> FTE | F45: =VLOOKUP(A45,File!$A:$J,6,FALSE) -> Chennai | G45: =VLOOKUP(A45,File!$A:$J,7,FALSE) -> CS26CS012 | H45: =VLOOKUP(A45,File!$A:$J,8,FALSE) -> Laksiya Vijayendran | I45: =VLOOKUP(A45,File!$A:$J,9,FALSE) -> 46343 | J45: =VLOOKUP(A45,File!$A:$K,11,FALSE) -> Nov 2026 | K45: =VLOOKUP(A45,File!$A:$K,10,FALSE) -> In-Training | L45: PG | M45: =VLOOKUP(A45,Response!$A:$M,7,) -> PG (Paying Guest) | N45: =VLOOKUP(A45,Response!$A:$M,8,) -> AADHI LAKSHMI PG FOR GENTS , Egattur | O45: =VLOOKUP(A45,Response!$A:$M,10,) -> 4 | P45: =VLOOKUP(A45,Response!$A:$M,12,) -> No | Q45: =VLOOKUP(A45,Response!$A:$M,11,) -> Siruseri | R45: Siruseri | S45: Red
A46: 2529565 | B46: =VLOOKUP(A46,File!$A:$J,2,FALSE) -> Yashas M | C46: =VLOOKUP(A46,File!$A:$J,5,FALSE) -> 46245 | D46: =VLOOKUP(A46,File!$A:$J,3,FALSE) -> Male | E46: =VLOOKUP(A46,File!$A:$J,4,FALSE) -> FTE | F46: =VLOOKUP(A46,File!$A:$J,6,FALSE) -> Chennai | G46: =VLOOKUP(A46,File!$A:$J,7,FALSE) -> CIS26MCPT024 | H46: =VLOOKUP(A46,File!$A:$J,8,FALSE) -> Ashiya Begam S | I46: =VLOOKUP(A46,File!$A:$J,9,FALSE) -> 46359 | J46: =VLOOKUP(A46,File!$A:$K,11,FALSE) -> Dec 2026 | K46: =VLOOKUP(A46,File!$A:$K,10,FALSE) -> In-Training | L46: PG | M46: =VLOOKUP(A46,Response!$A:$M,7,) -> PG (Paying Guest) | N46: =VLOOKUP(A46,Response!$A:$M,8,) -> AADHI LAKSHMI PG FOR GENTS , Egattur | O46: =VLOOKUP(A46,Response!$A:$M,10,) -> 2 | P46: =VLOOKUP(A46,Response!$A:$M,12,) -> No | Q46: =VLOOKUP(A46,Response!$A:$M,11,) -> Egattur | R46: Siruseri | S46: Red
A47: 2531832 | B47: =VLOOKUP(A47,File!$A:$J,2,FALSE) -> Lokesh Rajmal Thakare | C47: =VLOOKUP(A47,File!$A:$J,5,FALSE) -> 46254 | D47: =VLOOKUP(A47,File!$A:$J,3,FALSE) -> Male | E47: =VLOOKUP(A47,File!$A:$J,4,FALSE) -> FTE | F47: =VLOOKUP(A47,File!$A:$J,6,FALSE) -> Chennai | G47: =VLOOKUP(A47,File!$A:$J,7,FALSE) -> CS26CS012 | H47: =VLOOKUP(A47,File!$A:$J,8,FALSE) -> Laksiya Vijayendran | I47: =VLOOKUP(A47,File!$A:$J,9,FALSE) -> 46343 | J47: =VLOOKUP(A47,File!$A:$K,11,FALSE) -> Nov 2026 | K47: =VLOOKUP(A47,File!$A:$K,10,FALSE) -> In-Training | L47: PG | M47: =VLOOKUP(A47,Response!$A:$M,7,) -> PG (Paying Guest) | N47: =VLOOKUP(A47,Response!$A:$M,8,) -> AADHI LAKSHMI PG FOR GENTS , Egattur | O47: =VLOOKUP(A47,Response!$A:$M,10,) -> 4 | P47: =VLOOKUP(A47,Response!$A:$M,12,) -> No | Q47: =VLOOKUP(A47,Response!$A:$M,11,) -> Siruseri | R47: Siruseri | S47: Red
A48: 2529611 | B48: =VLOOKUP(A48,File!$A:$J,2,FALSE) -> Manikantareddy Muppidi | C48: =VLOOKUP(A48,File!$A:$J,5,FALSE) -> 46245 | D48: =VLOOKUP(A48,File!$A:$J,3,FALSE) -> Male | E48: =VLOOKUP(A48,File!$A:$J,4,FALSE) -> FTE | F48: =VLOOKUP(A48,File!$A:$J,6,FALSE) -> Chennai | G48: =VLOOKUP(A48,File!$A:$J,7,FALSE) -> CIS26MCPT021 | H48: =VLOOKUP(A48,File!$A:$J,8,FALSE) -> Uma Venkatachalam | I48: =VLOOKUP(A48,File!$A:$J,9,FALSE) -> 46364 | J48: =VLOOKUP(A48,File!$A:$K,11,FALSE) -> Dec 2026 | K48: =VLOOKUP(A48,File!$A:$K,10,FALSE) -> In-Training | L48: PG | M48: =VLOOKUP(A48,Response!$A:$M,7,) -> PG (Paying Guest) | N48: =VLOOKUP(A48,Response!$A:$M,8,) -> AADHI LAKSHMI PG FOR GENTS , Egattur | O48: =VLOOKUP(A48,Response!$A:$M,10,) -> 2 | P48: =VLOOKUP(A48,Response!$A:$M,12,) -> No | Q48: =VLOOKUP(A48,Response!$A:$M,11,) -> Siruseri | R48: Siruseri | S48: Red
...

Sheet Response
A1: 1 | B1: 2 | C1: 3 | D1: 4 | E1: 5 | F1: 6 | G1: 7 | H1: 8 | I1: 9 | J1: 10 | K1: 11 | L1: 12 | M1: 13
A2: ID2 | B2: Full Name (As per ID Card) Collected to accurately identify and contact associates during emergency situations and business continuity events. | C2: Your Mobile Number Collected to facilitate timely communication and coordination during emergencies, safety incidents, or business continuity events. | D2: Emergency Contact Mobile Number (Other than yours) Collected to enable communication with your designated emergency contact if you are unreachable during an emergency situation. | E2: Relationship with Emergency Contact You Have Shared Collected to understand your relationship with the emergency contact provided and facilitate appropriate communication during emergency situati... | F2: Primary Mode of Transport for Daily Commute to Office / Training Location Collected to understand commuting arrangements and support transportation-related contingency planning during emergency s... | G2: Current Accommodation Type Collected to understand your current living arrangement and support emergency preparedness and business continuity planning. | H2: Residence / Accommodation Name Collected to accurately identify your current place of residence and facilitate location-based support during emergencies. Example: Pasanga Paradise PG - Branch 1... | I2: Current Staying Address Collected to identify your current location and support emergency communication, safety measures, and business continuity response activities. Example: Pasanga Paradise ... | J2: Floor Number / Level Collected to help identify your exact location within the residence and support emergency response and evacuation planning when required. Examples: Ground Floor, 1st Floor,... | K2: Nearest Emergency Pickup / Nodal Point Collected to identify the nearest assembly or pickup location that may be used for emergency communication, transportation, and response activities. | L2: Do you have any relatives, friends, or guardians residing in Chennai who can provide temporary accommodation during emergency situations? Collected to assess the availability of local support and... | M2: Comments (If Any) Please provide any additional information that may be relevant for emergency preparedness, associate safety, or business continuity planning.
A3: 2529534 | B3: Dharanakumar V | C3: 9500093765 | D3: 9445450062 | E3: Parent | F3: Public Transport | G3: Permanent Residence (House/Home) | H3: - | I3: 23/1, Sunkuwar Lane, Triplicane, Chennai - 600005 | J3: 1 | K3: Karapakkam | L3: Yes | M3: -
A4: 2441374 | B4: Lawrance M | C4: 9585987522 | D4: 9486402432 | E4: Parent | F4: Company Transport (Shuttle) | G4: Rented House/Apartment | H4: - | I4: 3/68, 3rd Block, 4th Street, Mogappair West, Chennai-600037 | J4: 1 | K4: Wavin bus stop | L4: Yes
A5: 2531975 | B5: Roslin Nihara M | C5: 9363586357 | D5: 9940546955 | E5: Parent | F5: Public Transport | G5: Permanent Residence (House/Home) | I5: 3/11, KOTHARI NAGAR,1ST STREET, RAMAPURAM, CHENNAI:600089 | J5: GF | K5: RAMAPURAM | L5: Yes
A6: 2530216 | B6: Lipika c | C6: 9080030668 | D6: 9176674307 | E6: Parent | F6: Company Transport (Shuttle) | G6: PG (Paying Guest) | H6: Aura Nest Pg For Ladies | I6: Aura Nest Pg For Ladies 86-b, Mamoothiamman Street, City Park, Near Tcs New Building, Third Cross Road, Siruseri, Chennai-603103, Tamil Nadu | J6: 2 | K6: Egattur | L6: Yes | M6: none
A7: 2521623 | B7: Sana Sumera | C7: 8328355283 | D7: 9948165630 | E7: Parent | F7: Own Transport | G7: Hostel | H7: Aura Nest Pg For Ladies | I7: Aura Nest Pg for Ladies, 86-b, Mamoothiamman Street, City Park, Near Tcs New Building, Third Cross Road, Siruseri, Chennai-603103, Tamil Nadu. | J7: 2 | K7: Egattur | L7: No
A8: 2521079 | B8: Nalamothu Rishith | C8: 9391596766 | D8: 9393855851 | E8: Parent | F8: Company Transport (Shuttle) | G8: PG (Paying Guest) | H8: CNR GENTS PG BRANCH-1 | I8: CNR GENTS PG BRANCH-1, Mamoothiamman, 3rd St, Egattur, Tamil Nadu 603103 | J8: 3 | K8: Siruseri | L8: No
A9: 2507506 | B9: Rudra Naga Gani Varalakshmi Harika | C9: 7901545112 | D9: 9603397078 | E9: Parent | F9: Company Transport (Shuttle) | G9: PG (Paying Guest) | H9: Dheekshith Ladies Pg. | I9: Dheekshith Ladies Pg ,4/189, Periyar St, Uthandi, Egattur, Chennai-603103, Tamil Nadu . | J9: 2 | K9: Egattur | L9: No
A10: 2485951 | B10: Chaitanya Prakash Ghatbandhe | C10: 8080062382 | D10: 7276476809 | E10: Sibling | F10: Company Transport (Shuttle) | G10: PG (Paying Guest) | H10: Pasanga Paradise PG - Branch 1, Egattur | I10: Pasanga Paradise PG, Branch 1, Gangai Amman Kovil Street, Egattur, Siruseri, Tamil Nadu - 603103 | J10: 4 | K10: Egattur | L10: No
A11: 2521631 | B11: B Likith Vardhan Reddy | C11: 9347809128 | D11: 8897433271 | E11: Parent | F11: Company Transport (Shuttle) | G11: PG (Paying Guest) | H11: S S Gents Pg | I11: S S Gents Pg No 95 A, S S Gents Pg, City Park Sipcot, Mamoothy Amman Kovil 3rd Street, Sirucheri, Chennai-603103, Tamil Nadu https://jsdl.in/DT-20SESSXI1XT | J11: 4 | K11: Siruseri | L11: No | M11: lokesh - 863964472 roommate
A12: 2533065 | B12: Sri Venkat Nichenametla | C12: 7989497816 | D12: 9704435151 | E12: Parent | F12: Company Transport (Shuttle) | G12: PG (Paying Guest) | H12: Siddhus premium Mens pg | I12: Siddhus premium Mens pg, No 89c, city park layout, 3rd left street, egattur, siruseri, chennai, tamil nadu - 603103 | J12: 4 | K12: Siruseri | L12: Yes
A13: 2521700 | B13: Megha Roy | C13: 8240603936 | D13: 8910031982 | E13: Sibling | F13: Company Transport (Shuttle) | G13: PG (Paying Guest) | H13: Sns Pg For Ladies | I13: Sns Pg For Ladies 1/115, Panzhadiamman Kovilstreet, Egattur, Navalur, Chennai-600130, Tamil Nadu | J13: 3 | K13: Egattur | L13: No | M13: Likith Vardhan : 9347809128
A14: 2523372 | B14: Aditya Prabhakar Deshmukh | C14: 7385672298 | D14: 9420707746 | E14: Parent | F14: Company Transport (Shuttle) | G14: PG (Paying Guest) | H14: Soma Mens Stay | I14: Soma Mens Stay PLOT NO.15 B6, Soma Mens Stay, Sipcot IT Park, City Park Layout, 2nd Lane, Mamoothiamman St, Siruseri, Chennai-603103, Tamil Nadu https://jsdl.in/DT-20R2MCVYMKQ | J14: GF | K14: Siruseri | L14: Yes
A15: 2533210 | B15: VARSHA KODADI | C15: 9346977641 | D15: 9032735482 | E15: Parent | F15: Company Transport (Shuttle) | G15: PG (Paying Guest) | H15: UniQ PG | I15: UniQ PG, Dr Ambedkar St (near Gangaiamman Kovil Street), beside the street of Zaitoon Restaurant, Siruseri, Chennai, Tamil Nadu 600130 | J15: 2 | K15: Egattur | L15: No
A16: 2531306 | B16: Nishanthi K | C16: 7845252533 | D16: 9444681653 | E16: Parent | F16: Own Transport | G16: Permanent Residence (House/Home) | H16: "X" Block | I16: No: 14, "X" Block, RV Nagar, Jafferkhanpet, Chennai-600083 | J16: 1 | K16: Ashok Piller | L16: Yes
A17: 2521700 | B17: Megha Roy | C17: 8240603936 | D17: 8910031982 | E17: Sibling | F17: Company Transport (Shuttle) | G17: PG (Paying Guest) | H17: 1/115, Panzhadiamman Kovilstreet, Egattur, Navalur, Chennai-600130, Tamil Nadu | I17: 1/115, Panzhadiamman Kovilstreet, Egattur, Navalur, Chennai-600130, Tamil Nadu | J17: 3 | K17: Egattur | L17: No | M17: Roommate no: 7735844693 (Mauzila Nayek)
A18: 2521297 | B18: Buela Sindhu | C18: 9963122910 | D18: 9247837106 | E18: Parent | F18: Company Transport (Shuttle) | G18: PG (Paying Guest) | H18: 1/210a, Dr Ambedkar St, Egattur, Chennai, Tamil Nadu 600130 | I18: 1/210a, Dr Ambedkar St, Egattur, Chennai, Tamil Nadu 600130 | J18: 3 | K18: Egattur | L18: No
A19: 2523419 | B19: UZMA JABEEN SYED RAZA ALI | C19: 9657387047 | D19: 8237859277 | E19: Sibling | F19: Company Transport | G19: PG (Paying Guest) | H19: 1/210a, SRS Luxury PG for Ladies Branch 2, Dr. Ambedkar Street, Egattur | I19: 1/210a, SRS Luxury PG for Ladies, Dr. Ambedkar Street, Egattur, Siruseri, Tamil Nadu - 603103 | J19: 2 | K19: Egattur | L19: No
A20: 2523379 | B20: Abilash A | C20: 9344350896 | D20: 9791463769 | E20: Friend | F20: Public Transport | G20: Rented House/Apartment | H20: 1/749, Maruthi Nagar, Perungudi, Chennai 600096 | I20: 1/749, Maruthi Nagar, Perungudi, Chennai 600096 | J20: 1 | K20: Thoraipakkam | L20: Yes
A21: 2521836 | B21: Karan Saxena | C21: 9889262823 | D21: 8957980504 | E21: Sibling | F21: Company Transport (Shuttle) | G21: Relatives Residence | H21: 102B Greenwood, Hiranandani, Egattur | I21: 102B Greenwood, Hiranandani, Egattur | J21: 1 | K21: Egattur | L21: Yes
A22: 2521836 | B22: Karan Saxena | C22: 9889262823 | D22: 8102974622 | E22: Sibling | F22: Company Transport (Shuttle) | G22: Relatives Residence | H22: 102B Greenwood, Hiranandani, Egatur | I22: 102B Greenwood, Hiranandani, Egatur | J22: 1 | K22: Egattur | L22: Yes
A23: 2532952 | B23: Mallakuppam Manendra | C23: 6304733852 | D23: 7993484014 | E23: Parent | F23: Own Transport | G23: PG (Paying Guest) | H23: 105, Happy Homes Mens PG city park, Egatoor, Siruseri, Tamil Nadu 603103 | I23: 105, Happy Homes Mens PG city park, Egatoor, Siruseri, Tamil Nadu 603103 | J23: 1 | K23: Egattur | L23: No
A24: 2472446 | B24: Mohamed Harish | C24: 8220950542 | D24: 7200444061 | E24: Parent | F24: Company Transport (Shuttle) | G24: Rented House/Apartment | H24: 12 A, Sai Annai Avenue, Madha nagar, Madhananthapuram, Porur, Chennai | I24: 12 A, Sai Annai Avenue, Madha nagar, Madhananthapuram, Porur, Chennai | J24: 2 | K24: Porur | L24: No
A25: 2529576 | B25: Tharun B | C25: 9342709956 | D25: 9941566224 | E25: Parent | F25: Public Transport | G25: Rented House/Apartment | H25: 12/14 Rama rao garden 1st street royapettah chennai-14 | I25: 12/14 Rama rao garden 1st street royapettah chennai-14 | J25: GF | K25: Royapettah | L25: Yes
A26: 2521188 | B26: Meghana S | C26: 9019848955 | D26: 9535644152 | E26: Parent | F26: Company Transport (Shuttle) | G26: Rented House/Apartment | H26: 1-285, Sonachalam street, Rajiv Gandhi salai, OMR, Chennai-600130 | I26: 1-285, Sonachalam street, Rajiv Gandhi salai, OMR, Chennai-600130 | J26: 2 | K26: Navalur | L26: No
A27: 2521188 | B27: Meghana S | C27: 9019848955 | D27: 9535644152 | E27: Parent | F27: Company Transport (Shuttle) | G27: Rented House/Apartment | H27: 1-285, Sonachalam street, Rajiv Gandhi salai, OMR, Chennai-600130 | I27: 1-285, Sonachalam street, Rajiv Gandhi salai, OMR, Chennai-600130 | J27: 2 | K27: Navalur | L27: No
A28: 2521188 | B28: Meghana S | C28: 9019848955 | D28: 9535644152 | E28: Parent | F28: Company Transport (Shuttle) | G28: Rented House/Apartment | H28: 1-285, Sonachalam street, Rajiv Gandhi salai, OMR, Chennai-600130 | I28: 1-285, Sonachalam street, Rajiv Gandhi salai, OMR, Chennai-600130 | J28: 2 | K28: Navalur | L28: No
A29: 2523447 | B29: Saravanan A | C29: 7598027746 | D29: 9487537746 | E29: Parent | F29: Public Transport | G29: PG (Paying Guest) | H29: 13 A, Narayanan Gents PG, Srivijayaganapathy nagar, mayana salai, navalur - 600130 | I29: 13 A, Narayanan Gents PG, Srivijayaganapathy nagar, mayana salai, navalur - 600130 | J29: 3 | K29: Navalur | L29: No
A30: 2523416 | B30: Balakumaran Bommudurai | C30: 6381778820 | D30: 9943673263 | E30: Parent | F30: Public Transport | G30: Rented House/Apartment | H30: 14 Valluvar high road ,subash nagar,chromepet,600044 | I30: 14 Valluvar high road ,subash nagar,chromepet,600044 | J30: 1 | K30: Chromepet | L30: Yes
A31: 2437335 | B31: Viveka Preethi | C31: 9080537060 | D31: 9600129080 | E31: Spouse | F31: Company Transport (Shuttle) | G31: Rented House/Apartment | H31: 18/A, Chandra Illam, Venkatachalapathy Street, Sembakkam - 600 073 | I31: 18/A, Chandra Illam, Venkatachalapathy Street, Sembakkam - 600 073 | J31: 1 | K31: Medavakkam | L31: Yes | M31: Nil
A32: 2521255 | B32: Vikil Reddy Vangala | C32: 9505616743 | D32: 789377371 | E32: Parent | F32: Company Transport (Shuttle) | G32: PG (Paying Guest) | H32: 1st Left , Sipcot IT park , city park layout, Plot no - 56P, Siruseri , Egattur , Tamilnadu 603103 | I32: 1st Left , Sipcot IT park , city park layout, Plot no - 56P, Siruseri , Egattur , Tamilnadu 603103 | J32: 1 | K32: Siruseri | L32: No
A33: 2532911 | B33: Billakanti Mokshith | C33: 9573761703 | D33: 9849384269 | E33: Parent | F33: Company Transport (Shuttle) | G33: PG (Paying Guest) | H33: 1st Left, Sipcot It Park, City Park Layout, Plot No -56P, Siruseri, Egattur, TamilNadu 603103 | I33: 1st Left, Sipcot It Park, City Park Layout, Plot No -56P, Siruseri, Egattur, TamilNadu 603103 | J33: 1 | K33: Siruseri | L33: No
A34: 2530219 | B34: Venkata Thejeswar Reddy Yerasu | C34: 9059025079 | D34: 6381245534 | E34: Sibling | F34: Public Transport | G34: Rented House/Apartment | H34: 1st street backside of the JS Global School, NO1 lake view point, Rajiv Gandhi salai,Ponniamman ,sholinganallur | I34: 1st street backside of the JS Global School, NO1 lake view point, Rajiv Gandhi salai, sholinganallur, Tamilnadu | J34: GF | K34: Sholinganallur | L34: No
A35: 2315792 | B35: Adarsh J Nair | C35: 6380216432 | D35: 9150760027 | E35: Parent | F35: Own Transport | G35: Permanent Residence (House/Home) | H35: 2/55. Thiruvalluvar street , Navalur | I35: 2/55. Thiruvalluvar street , Navalur , 600130 | J35: 1 | K35: Navalur | L35: No | M35: NA
A36: 2533141 | B36: Srimattirumalapeddinti Sai Bala Harini | C36: 7995615118 | D36: 9959873888 | E36: Sibling | F36: Company Transport (Shuttle) | G36: PG (Paying Guest) | H36: 206,4th floor,New Vaishnavi elite pg,egattur,siruseri,tambaram district | I36: 206,4th floor,New Vaishnavi elite pg, egattur, siruseri , tambaram district ,tamil nadu | J36: 4 | K36: Egattur | L36: No
A37: 2533023 | B37: Girija Sai Siri Cherukuri | C37: 8919546878 | D37: 8143120465 | E37: Sibling | F37: Company Transport (Shuttle) | G37: PG (Paying Guest) | H37: 206,Vaishnavi Elite PG-Chennai,Egattur | I37: 206,Vaishnavi Elite PG, Gangai Amman Kovil Street, Egattur, Siruseri, Tamil Nadu - 603103 | J37: GF | K37: Egattur | L37: No
A38: 2531986 | B38: Narasani Udaya Teja | C38: 6301074771 | D38: 9036400498 | E38: Sibling | F38: Company Transport (Shuttle) | G38: PG (Paying Guest) | H38: 25, St Thomas St,near Navalur, Tollgate, Egattur, Chennai | I38: 25, St Thomas St,near Navalur, Tollgate, Egattur, Chennai | J38: GF | K38: Navalur | L38: No
A39: 2521370 | B39: Maddila Keerthana | C39: 7989655434 | D39: 7661043579 | E39: Parent | F39: Company Transport (Shuttle) | G39: PG (Paying Guest) | H39: 4/187, Periyar Street, Old Mahabalipuram Road, Egattur, Chennai, Tamil Nadu 600130 | I39: 4/187, Periyar Street, Old Mahabalipuram Road, Egattur, Chennai, Tamil Nadu 600130 | J39: 3 | K39: Egattur | L39: No
A40: 2521065 | B40: Dadiboina Deepika | C40: 6281477470 | D40: 8688827347 | E40: Parent | F40: Company Transport (Shuttle) | G40: PG (Paying Guest) | H40: 4/201, Sai teja ladies hostel | I40: periyar Street, Uthandi, Egattur, Chengalpattu, Tamil Nadu, 600130 | J40: 3 | K40: Egattur | L40: No
...

Sheet File
A1: 1 | B1: 2 | C1: 3 | D1: 4 | E1: 5 | F1: 6 | G1: 7 | H1: 8 | I1: 9 | J1: 10 | K1: 11
A2: Associate Id | B2: Name | C2: Gender | D2: Joiners Type | E2: DOJ | F2: Joining Location | G2: Cohort Code | H2: Coach Name | I2: Revised - Tentative Release Date | J2: Final Status | K2: Tentative/Actual Release Month
A3: 2476045 | B3: Jui Sachin Shaha | C3: Female | D3: FTE | E3: 46042 | F3: Chennai | G3: EPS26OSPAT004 | H3: Paul Franklin | I3: 46203 | J3: Training - ON Hold
A4: 2478572 | B4: Aman LNU | C4: Male | D4: CSD | E4: 46254 | F4: Chennai | G4: INTFE26FE002 | H4: Muhil Indrajith | I4: 46310 | J4: In-Training | K4: Oct 2026
A5: 2479335 | B5: Surya Pratap Singh | C5: Male | D5: CSD | E5: 46254 | F5: Chennai | G5: INTFE26FE002 | H5: Muhil Indrajith | I5: 46310 | J5: In-Training | K5: Oct 2026
A6: 2479361 | B6: B Archana | C6: Female | D6: CSD | E6: 46254 | F6: Chennai | G6: INTFE26FE001 | H6: Grace Esther S | I6: 46310 | J6: In-Training | K6: Oct 2026
A7: 2479396 | B7: Daggupati Nirali | C7: Female | D7: CSD | E7: 46254 | F7: Chennai | G7: INTFE26FE001 | H7: Grace Esther S | I7: 46310 | J7: In-Training | K7: Oct 2026
A8: 2479899 | B8: Rutuja Satish Kohale | C8: Female | D8: FTE | E8: 46053 | F8: Chennai | G8: ADM26ISMO010 | H8: Thomas Naveen. J | I8: 46301 | J8: In-Training | K8: Oct 2026
A9: 2480129 | B9: Adnan Ahemad Navidoddin Sayyad | C9: Male | D9: CSD | E9: 46254 | F9: Chennai | G9: INTFE26FE001 | H9: Grace Esther S | I9: 46310 | J9: In-Training | K9: Oct 2026
A10: 2480265 | B10: Kunal Ashok Choure | C10: Male | D10: CSD | E10: 46254 | F10: Chennai | G10: INTFE26FE002 | H10: Muhil Indrajith | I10: 46310 | J10: In-Training | K10: Oct 2026
A11: 2480270 | B11: Sushant Sanjay Ambekar | C11: Male | D11: CSD | E11: 46254 | F11: Chennai | G11: INTFE26FE002 | H11: Muhil Indrajith | I11: 46310 | J11: In-Training | K11: Oct 2026
A12: 2480307 | B12: Nandhitha B | C12: Female | D12: CSD | E12: 46254 | F12: Chennai | G12: INTFE26FE001 | H12: Grace Esther S | I12: 46310 | J12: In-Training | K12: Oct 2026
A13: 2481699 | B13: Sivasakthi S | C13: Male | D13: FTE | E13: 46058 | F13: Chennai | G13: CS26CS008 | H13: Kishorekumar P | I13: 46323 | J13: In-Training | K13: Oct 2026
A14: 2484070 | B14: Umar Ashif M | C14: Male | D14: FTE | E14: 46067 | F14: Chennai | G14: QEA26QEPT023 | H14: Sweta Thoppil | I14: 46314 | J14: In-Training | K14: Oct 2026
A15: 2485779 | B15: Naman,Modi | C15: Male | D15: CSD | E15: 46254 | F15: Chennai | G15: INTFE26FE002 | H15: Muhil Indrajith | I15: 46310 | J15: In-Training | K15: Oct 2026
... A1000: 2526174 | B1000: Abinaya Ramesh | C1000: Female | D1000: FTE | E1000: 46231 | F1000: Chennai | G1000: CIS26DWP024 | H1000: Lakavath Udhaya Bhavana | I1000: 46286 | J1000: In-Training | K1000: Sep 2026
A1001: 2526590 | B1001: Soniya Satish Mate | C1001: Female | D1001: FTE | E1001: 46233 | F1001: Chennai | G1001: QEA26JP001 | H1001: Ajiesya D P | J1001: Training - ON Hold
A1002: 2526591 | B1002: Rupesh Kailas Deshmukh | C1002: Male | D1002: FTE | E1002: 46233 | F1002: Chennai | G1002: QEA26JP002 | H1002: Ajiesya D P | J1002: Training - ON Hold
A1003: 2526592 | B1003: Krishnaraj G | C1003: Male | D1003: FTE | E1003: 46233 | F1003: Chennai | G1003: QEA26JP001 | H1003: Ajiesya D P | J1003: Training - ON Hold
A1004: 2526593 | B1004: Sumitha S | C1004: Female | D1004: FTE | E1004: 46233 | F1004: Chennai | G1004: QEA26JP001 | H1004: Ajiesya D P | J1004: Training - ON Hold
A1005: 2526594 | B1005: Rahul M | C1005: Male | D1005: FTE | E1005: 46233 | F1005: Chennai | G1005: QEA26JP001 | H1005: Ajiesya D P | J1005: Training - ON Hold
A1006: 2526595 | B1006: Shashwath Shankar R | C1006: Male | D1006: FTE | E1006: 46233 | F1006: Chennai | G1006: QEA26JP001 | H1006: Ajiesya D P | J1006: Training - ON Hold
A1007: 2526597 | B1007: Sowmiya B | C1007: Female | D1007: FTE | E1007: 46233 | F1007: Chennai | G1007: QEA26JP001 | H1007: Ajiesya D P | J1007: Training - ON Hold
A1008: 2526600 | B1008: Chetan Dipak Patil | C1008: Male | D1008: FTE | E1008: 46233 | F1008: Chennai | G1008: QEA26JP001 | H1008: Ajiesya D P | J1008: Training - ON Hold
A1009: 2526602 | B1009: Lagad Sampada Santosh | C1009: Female | D1009: FTE | E1009: 46233 | F1009: Chennai | G1009: QEA26JP002 | H1009: Ajiesya D P | J1009: Training - ON Hold
A1010: 2526610 | B1010: Ashwin Sundar V S | C1010: Male | D1010: FTE | E1010: 46233 | F1010: Chennai | G1010: QEA26JP001 | H1010: Ajiesya D P | J1010: Training - ON Hold
A1011: 2526615 | B1011: Janarthanan T | C1011: Male | D1011: FTE | E1011: 46233 | F1011: Chennai | G1011: QEA26JP002 | H1011: Ajiesya D P | J1011: Training - ON Hold
A1012: 2526621 | B1012: Sahil Ashok Thorat | C1012: Male | D1012: FTE | E1012: 46233 | F1012: Chennai | G1012: QEA26JP001 | H1012: Ajiesya D P | J1012: Training - ON Hold
A1013: 2529490 | B1013: Ragul A | C1013: Male | D1013: FTE | E1013: 46245 | F1013: Chennai | G1013: CIS26MCPT021 | H1013: Uma Venkatachalam | I1013: 46364 | J1013: In-Training | K1013: Dec 2026
A1014: 2529492 | B1014: Sivapavani Vara | C1014: Female | D1014: FTE | E1014: 46245 | F1014: Chennai | G1014: CIS26MCPT021 | H1014: Uma Venkatachalam | I1014: 46364 | J1014: In-Training | K1014: Dec 2026
A1015: 2529493 | B1015: Vaibhav Santosh Babar | C1015: Male | D1015: FTE | E1015: 46245 | F1015: Chennai | G1015: CIS26MCPT025 | H1015: Vignesh S | I1015: 46359 | J1015: In-Training | K1015: Dec 2026
A1016: 2529494 | B1016: Nikhil Sanjay Jadhav | C1016: Male | D1016: FTE | E1016: 46245 | F1016: Chennai | G1016: CIS26MCPT021 | H1016: Uma Venkatachalam | I1016: 46364 | J1016: In-Training | K1016: Dec 2026
A1017: 2529495 | B1017: Supreeth A S | C1017: Male | D1017: FTE | E1017: 46245 | F1017: Chennai | G1017: CIS26MCPT024 | H1017: Ashiya Begam S | I1017: 46359 | J1017: In-Training | K1017: Dec 2026
A1018: 2529498 | B1018: Amin Nashir Shaikh | C1018: Male | D1018: FTE | E1018: 46245 | F1018: Chennai | G1018: CIS26MCPT026 | H1018: Mohamed Harish | I1018: 46364 | J1018: In-Training | K1018: Dec 2026
A1019: 2529499 | B1019: Ramya Varshini GH | C1019: Female | D1019: FTE | E1019: 46245 | F1019: Chennai | G1019: CIS26MCPT024 | H1019: Ashiya Begam S | I1019: 46359 | J1019: In-Training | K1019: Dec 2026
